<?xml version="1.0"?>
<robot name="WPR1">

  <!-- material -->
  <material name = "black">
    <color rgba = "0.01 0.01 0.01 1"/>
  </material>
  <material name = "grey">
    <color rgba = "0.2 0.2 0.2 1"/>
  </material>
  <material name = "blue">
    <color rgba = "0.2 0.2 0.9 1"/>
  </material>


<link name="base_footprint">
    <visual>
      <origin xyz="0 0 0" rpy="0 0 0" />
      <geometry>
        <box size="0.05 0.05 0.001" />
      </geometry>
      <material name="TransparentGreen" />
    </visual>
    <collision>
      <origin xyz="0 0 .1" rpy="0 0 0" />
      <geometry>
        <box size="0.76 0.5 .2"/>
      </geometry>
    </collision>
</link>

<joint name="base_joint" type="fixed">
  <origin xyz="0 0 0" rpy="0 0 0" />
  <parent link="base_footprint"/>
  <child link="base_link" />
</joint>

  <!-- base -->
  <link name="base_link">
  <visual>
   <geometry>
    <mesh filename="package://wpr1_bringup/meshes/base.dae" scale="1 1 1"/>
   </geometry>
   <origin rpy = "1.57 0 -1.57" xyz = "0.22 .293 0"/>
  </visual>
  </link>

  <!-- torso -->
  <link name = "torso_link">
    <visual>
      <geometry>
        <mesh filename="package://wpr1_bringup/meshes/torso.dae" scale="1 1 1"/>
      </geometry>
      <origin rpy = "1.57 0 0" xyz = "0 0.1405 0"/>
    </visual>
  </link>
  <joint name = "base_to_torso" type="prismatic">
    <parent link = "base_link"/>
    <child link = "torso_link"/>
    <axis xyz="0 0 1"/>
    <limit effort="1000.0" lower="0" upper="0.4" velocity="0.5"/>
    <origin rpy="0 0 0" xyz="-0.255 0 0.287"/> <!--pos-->
  </joint>

  <!-- upper arm -->
  <link name = "upperarm_link">
    <visual>
      <geometry>
        <mesh filename="package://wpr1_bringup/meshes/upperarm.dae" scale="1 1 1"/>
      </geometry>
      <origin rpy = "0 -1.57 0" xyz = "0.235 -0.087 -0.046"/>
    </visual>
  </link>
  <joint name = "torso_to_upperarm" type="revolute">
    <parent link = "torso_link"/>
    <child link = "upperarm_link"/>
    <axis xyz="0 1 0"/>
    <limit effort="1000.0" lower="-1.57" upper="1.57" velocity="0.5"/>
    <origin xyz="0.266 0 0.55" rpy="0 0 0" /> <!--pos-->
  </joint>

  <!-- fore arm -->
  <link name = "forearm_link">
    <visual>
      <geometry>
        <mesh filename="package://wpr1_bringup/meshes/forearm.dae" scale="1 1 1"/>
      </geometry>
      <origin rpy = "1.57 1.57 0" xyz = "-0.033 0.07 0.046"/>
    </visual>
  </link>
  <joint name = "upperarm_to_forearm" type="revolute">
    <parent link = "upperarm_link"/>
    <child link = "forearm_link"/>
    <axis xyz="0 1 0"/>
    <limit effort="1000.0" lower="-1.57" upper="1.57" velocity="0.5"/>
    <origin xyz="0.168 0 0" rpy="0 0 0" /> <!--pos-->
  </joint>

  <!-- palm -->
  <link name = "palm_link">
    <visual>
      <geometry>
        <mesh filename="package://wpr1_bringup/meshes/palm.dae" scale="1 1 1"/>
      </geometry>
      <origin rpy = "0 3.14 -1.57" xyz = "0 -0.0655 0.069"/>
    </visual>
  </link>
  <joint name = "forearm_to_palm" type="revolute">
    <parent link = "forearm_link"/>
    <child link = "palm_link"/>
    <axis xyz="1 0 0"/>
    <limit effort="1000.0" lower="-3.14" upper="3.14" velocity="0.5"/>
    <origin xyz="0.209 0 0" rpy="0 0 0" /> <!--pos-->
  </joint>

  <!-- finger -->
    <link name = "mani_left_finger">
      <visual>
          <geometry>
              <mesh filename="package://wpr1_bringup/meshes/finger.dae" scale="1 1 1"/>
          </geometry>
          <origin rpy = "0 0 -1.57" xyz = "-0.005 0.005 -0.0195"/>
      </visual>
  </link>
  <joint name = "mani_palm_finger" type = "revolute">
      <parent link = "palm_link"/>
      <child link = "mani_left_finger"/>
      <origin xyz = "0.188 0.06 0"/>
      <axis xyz = "0 0 1"/>
      <limit effort = "1000.0" lower="0" upper="1.0" velocity="0.5"/>
  </joint>

   <link name = "mani_right_finger">
            <visual>
                <geometry>
                    <mesh filename="package://wpr1_bringup/meshes/finger.dae" scale="1 1 1"/>
                </geometry>
                <origin rpy = "3.14 0 1.57" xyz = "-0.005 -0.005 0.0195"/>
            </visual>
        </link>
        <joint name = "mani_palm_right_finger" type = "revolute">
            <parent link = "palm_link"/>
            <child link = "mani_right_finger"/>
            <origin xyz = "0.188 -0.06 0"/>
            <axis xyz = "0 0 -1"/>
            <limit effort = "1000.0" lower="0" upper="1.0" velocity="0.5"/>
            <mimic joint = "mani_palm_finger" multiplier = "1" offset = "0"/>
        </joint>
  <!-- *****************-->
  <!-- Lidar -->
  <link name = "laser">
    <visual>
    <geometry>
      <cylinder length="0.03" radius="0.03"/>
    </geometry>
    <origin rpy = "0 0 0" xyz = "0 0 0"/>
    </visual>
  </link>
  <joint name="laser_joint" type="fixed">
      <origin rpy="0 0 0" xyz="0.19 0 0"  /> <!--pos-->
      <parent link="base_link" />
      <child link="laser" />
  </joint>

  <!-- Kinect -->
<link name = "kinect2_dock">
  <visual>
   <geometry>
    <!--<box size=".01 .25 .07"/>-->
    <box size="0 0 0"/>
   </geometry>
   <origin rpy = "0 0 0" xyz = "0 0 0"/>
   <material name = "red"/>
  </visual>
</link>
<joint name="kinect_height" type="prismatic">
    <parent link="torso_link"/>
    <child link="kinect2_dock"/>
    <limit effort="1000.0" lower="0" upper="1.35" velocity="0.5"/>
    <origin xyz="0.174 0 0" rpy="0 -1.5707963 0"/>
  </joint>

<link name = "kinect2_ir_optical_frame">
  <visual>
   <geometry>
    <!-- <box size=".25 .04 .07"/>-->
    <box size="0 0 0"/>
   </geometry>
   <origin xyz = "0 0 0" rpy = "0 0 0"/>
   <material name = "blue"/>
  </visual>
</link>

<joint name="kinect_pitch" type="revolute">
    <axis xyz="1 0 0"/>
    <limit effort="1000.0" lower="-1.57" upper="1.57" velocity="0.5"/>
    <origin xyz="0 0 0" rpy="3.1415926 0 -1.5707963" /> <!--pos-->
    <parent link="kinect2_dock" />
    <child link="kinect2_ir_optical_frame" />
</joint>

<link name = "kinect2_rgb_optical_frame">
  <visual>
   <geometry>
    <box size="0 0 0"/>
   </geometry>
   <origin rpy = "0 0 0" xyz = "0 0 0" />
   <material name = "blue" />
  </visual>
</link>
<joint name="kinect_hd_joint" type="fixed">
    <origin xyz="0 0 0" rpy="0 0 0" /> <!--pos-->
    <parent link="kinect2_ir_optical_frame" />
    <child link="kinect2_rgb_optical_frame" />
</joint>
</robot>
